2023-12-05 13:06:52,882 ERROR scheduler Exception in Enqueue Events for Site library.test
Traceback (most recent call last):
  File "/home/its_pt/Work/frappe_learn/frappe-bench/env/lib/python3.10/site-packages/pymysql/connections.py", line 644, in connect
    sock = socket.create_connection(
  File "/home/its_pt/.pyenv/versions/3.10.11/lib/python3.10/socket.py", line 845, in create_connection
    raise err
  File "/home/its_pt/.pyenv/versions/3.10.11/lib/python3.10/socket.py", line 833, in create_connection
    sock.connect(sa)
ConnectionRefusedError: [Errno 111] Connection refused

During handling of the above exception, another exception occurred:

Traceback (most recent call last):
  File "/home/its_pt/Work/frappe_learn/frappe-bench/apps/frappe/frappe/utils/scheduler.py", line 73, in enqueue_events_for_site
    if is_scheduler_inactive():
  File "/home/its_pt/Work/frappe_learn/frappe-bench/apps/frappe/frappe/utils/scheduler.py", line 110, in is_scheduler_inactive
    if is_scheduler_disabled(verbose=verbose):
  File "/home/its_pt/Work/frappe_learn/frappe-bench/apps/frappe/frappe/utils/scheduler.py", line 123, in is_scheduler_disabled
    frappe.db.get_single_value("System Settings", "enable_scheduler")
  File "/home/its_pt/Work/frappe_learn/frappe-bench/apps/frappe/frappe/database/database.py", line 776, in get_single_value
    ).run()
  File "/home/its_pt/Work/frappe_learn/frappe-bench/apps/frappe/frappe/query_builder/utils.py", line 87, in execute_query
    result = frappe.db.sql(query, params, *args, **kwargs)  # nosemgrep
  File "/home/its_pt/Work/frappe_learn/frappe-bench/apps/frappe/frappe/database/database.py", line 194, in sql
    self.connect()
  File "/home/its_pt/Work/frappe_learn/frappe-bench/apps/frappe/frappe/database/database.py", line 107, in connect
    self._conn = self.get_connection()
  File "/home/its_pt/Work/frappe_learn/frappe-bench/apps/frappe/frappe/database/mariadb/database.py", line 102, in get_connection
    conn = self._get_connection()
  File "/home/its_pt/Work/frappe_learn/frappe-bench/apps/frappe/frappe/database/mariadb/database.py", line 108, in _get_connection
    return self.create_connection()
  File "/home/its_pt/Work/frappe_learn/frappe-bench/apps/frappe/frappe/database/mariadb/database.py", line 111, in create_connection
    return pymysql.connect(**self.get_connection_settings())
  File "/home/its_pt/Work/frappe_learn/frappe-bench/env/lib/python3.10/site-packages/pymysql/connections.py", line 358, in __init__
    self.connect()
  File "/home/its_pt/Work/frappe_learn/frappe-bench/env/lib/python3.10/site-packages/pymysql/connections.py", line 711, in connect
    raise exc
pymysql.err.OperationalError: (2003, "Can't connect to MySQL server on '127.0.0.1' ([Errno 111] Connection refused)")
2023-12-05 13:07:53,009 ERROR scheduler Exception in Enqueue Events for Site library.test
Traceback (most recent call last):
  File "/home/its_pt/Work/frappe_learn/frappe-bench/env/lib/python3.10/site-packages/pymysql/connections.py", line 644, in connect
    sock = socket.create_connection(
  File "/home/its_pt/.pyenv/versions/3.10.11/lib/python3.10/socket.py", line 845, in create_connection
    raise err
  File "/home/its_pt/.pyenv/versions/3.10.11/lib/python3.10/socket.py", line 833, in create_connection
    sock.connect(sa)
ConnectionRefusedError: [Errno 111] Connection refused

During handling of the above exception, another exception occurred:

Traceback (most recent call last):
  File "/home/its_pt/Work/frappe_learn/frappe-bench/apps/frappe/frappe/utils/scheduler.py", line 73, in enqueue_events_for_site
    if is_scheduler_inactive():
  File "/home/its_pt/Work/frappe_learn/frappe-bench/apps/frappe/frappe/utils/scheduler.py", line 110, in is_scheduler_inactive
    if is_scheduler_disabled(verbose=verbose):
  File "/home/its_pt/Work/frappe_learn/frappe-bench/apps/frappe/frappe/utils/scheduler.py", line 123, in is_scheduler_disabled
    frappe.db.get_single_value("System Settings", "enable_scheduler")
  File "/home/its_pt/Work/frappe_learn/frappe-bench/apps/frappe/frappe/database/database.py", line 776, in get_single_value
    ).run()
  File "/home/its_pt/Work/frappe_learn/frappe-bench/apps/frappe/frappe/query_builder/utils.py", line 87, in execute_query
    result = frappe.db.sql(query, params, *args, **kwargs)  # nosemgrep
  File "/home/its_pt/Work/frappe_learn/frappe-bench/apps/frappe/frappe/database/database.py", line 194, in sql
    self.connect()
  File "/home/its_pt/Work/frappe_learn/frappe-bench/apps/frappe/frappe/database/database.py", line 107, in connect
    self._conn = self.get_connection()
  File "/home/its_pt/Work/frappe_learn/frappe-bench/apps/frappe/frappe/database/mariadb/database.py", line 102, in get_connection
    conn = self._get_connection()
  File "/home/its_pt/Work/frappe_learn/frappe-bench/apps/frappe/frappe/database/mariadb/database.py", line 108, in _get_connection
    return self.create_connection()
  File "/home/its_pt/Work/frappe_learn/frappe-bench/apps/frappe/frappe/database/mariadb/database.py", line 111, in create_connection
    return pymysql.connect(**self.get_connection_settings())
  File "/home/its_pt/Work/frappe_learn/frappe-bench/env/lib/python3.10/site-packages/pymysql/connections.py", line 358, in __init__
    self.connect()
  File "/home/its_pt/Work/frappe_learn/frappe-bench/env/lib/python3.10/site-packages/pymysql/connections.py", line 711, in connect
    raise exc
pymysql.err.OperationalError: (2003, "Can't connect to MySQL server on '127.0.0.1' ([Errno 111] Connection refused)")
2023-12-05 13:10:38,093 ERROR scheduler Exception in Enqueue Events for Site library.test
Traceback (most recent call last):
  File "/home/its_pt/Work/frappe_learn/frappe-bench/env/lib/python3.10/site-packages/pymysql/connections.py", line 644, in connect
    sock = socket.create_connection(
  File "/home/its_pt/.pyenv/versions/3.10.11/lib/python3.10/socket.py", line 845, in create_connection
    raise err
  File "/home/its_pt/.pyenv/versions/3.10.11/lib/python3.10/socket.py", line 833, in create_connection
    sock.connect(sa)
ConnectionRefusedError: [Errno 111] Connection refused

During handling of the above exception, another exception occurred:

Traceback (most recent call last):
  File "/home/its_pt/Work/frappe_learn/frappe-bench/apps/frappe/frappe/utils/scheduler.py", line 73, in enqueue_events_for_site
    if is_scheduler_inactive():
  File "/home/its_pt/Work/frappe_learn/frappe-bench/apps/frappe/frappe/utils/scheduler.py", line 110, in is_scheduler_inactive
    if is_scheduler_disabled(verbose=verbose):
  File "/home/its_pt/Work/frappe_learn/frappe-bench/apps/frappe/frappe/utils/scheduler.py", line 123, in is_scheduler_disabled
    frappe.db.get_single_value("System Settings", "enable_scheduler")
  File "/home/its_pt/Work/frappe_learn/frappe-bench/apps/frappe/frappe/database/database.py", line 776, in get_single_value
    ).run()
  File "/home/its_pt/Work/frappe_learn/frappe-bench/apps/frappe/frappe/query_builder/utils.py", line 87, in execute_query
    result = frappe.db.sql(query, params, *args, **kwargs)  # nosemgrep
  File "/home/its_pt/Work/frappe_learn/frappe-bench/apps/frappe/frappe/database/database.py", line 194, in sql
    self.connect()
  File "/home/its_pt/Work/frappe_learn/frappe-bench/apps/frappe/frappe/database/database.py", line 107, in connect
    self._conn = self.get_connection()
  File "/home/its_pt/Work/frappe_learn/frappe-bench/apps/frappe/frappe/database/mariadb/database.py", line 102, in get_connection
    conn = self._get_connection()
  File "/home/its_pt/Work/frappe_learn/frappe-bench/apps/frappe/frappe/database/mariadb/database.py", line 108, in _get_connection
    return self.create_connection()
  File "/home/its_pt/Work/frappe_learn/frappe-bench/apps/frappe/frappe/database/mariadb/database.py", line 111, in create_connection
    return pymysql.connect(**self.get_connection_settings())
  File "/home/its_pt/Work/frappe_learn/frappe-bench/env/lib/python3.10/site-packages/pymysql/connections.py", line 358, in __init__
    self.connect()
  File "/home/its_pt/Work/frappe_learn/frappe-bench/env/lib/python3.10/site-packages/pymysql/connections.py", line 711, in connect
    raise exc
pymysql.err.OperationalError: (2003, "Can't connect to MySQL server on '127.0.0.1' ([Errno 111] Connection refused)")
2023-12-05 16:00:10,558 ERROR scheduler Exception in Enqueue Events for Site library.test
Traceback (most recent call last):
  File "/home/its_pt/Work/frappe_learn/frappe-bench/env/lib/python3.10/site-packages/redis/connection.py", line 1092, in get_connection
    if connection.can_read():
  File "/home/its_pt/Work/frappe_learn/frappe-bench/env/lib/python3.10/site-packages/redis/connection.py", line 478, in can_read
    return self._parser.can_read(timeout)
  File "/home/its_pt/Work/frappe_learn/frappe-bench/env/lib/python3.10/site-packages/redis/_parsers/hiredis.py", line 75, in can_read
    return self.read_from_socket(timeout=timeout, raise_on_timeout=False)
  File "/home/its_pt/Work/frappe_learn/frappe-bench/env/lib/python3.10/site-packages/redis/_parsers/hiredis.py", line 86, in read_from_socket
    raise ConnectionError(SERVER_CLOSED_CONNECTION_ERROR)
redis.exceptions.ConnectionError: Connection closed by server.

During handling of the above exception, another exception occurred:

Traceback (most recent call last):
  File "/home/its_pt/Work/frappe_learn/frappe-bench/env/lib/python3.10/site-packages/redis/connection.py", line 264, in connect
    sock = self.retry.call_with_retry(
  File "/home/its_pt/Work/frappe_learn/frappe-bench/env/lib/python3.10/site-packages/redis/retry.py", line 46, in call_with_retry
    return do()
  File "/home/its_pt/Work/frappe_learn/frappe-bench/env/lib/python3.10/site-packages/redis/connection.py", line 265, in <lambda>
    lambda: self._connect(), lambda error: self.disconnect(error)
  File "/home/its_pt/Work/frappe_learn/frappe-bench/env/lib/python3.10/site-packages/redis/connection.py", line 627, in _connect
    raise err
  File "/home/its_pt/Work/frappe_learn/frappe-bench/env/lib/python3.10/site-packages/redis/connection.py", line 615, in _connect
    sock.connect(socket_address)
ConnectionRefusedError: [Errno 111] Connection refused

During handling of the above exception, another exception occurred:

Traceback (most recent call last):
  File "/home/its_pt/Work/frappe_learn/frappe-bench/apps/frappe/frappe/utils/scheduler.py", line 76, in enqueue_events_for_site
    enqueue_events()
  File "/home/its_pt/Work/frappe_learn/frappe-bench/apps/frappe/frappe/utils/scheduler.py", line 93, in enqueue_events
    if job_type.enqueue():
  File "/home/its_pt/Work/frappe_learn/frappe-bench/apps/frappe/frappe/core/doctype/scheduled_job_type/scheduled_job_type.py", line 59, in enqueue
    if not self.is_job_in_queue():
  File "/home/its_pt/Work/frappe_learn/frappe-bench/apps/frappe/frappe/core/doctype/scheduled_job_type/scheduled_job_type.py", line 80, in is_job_in_queue
    return is_job_enqueued(self.rq_job_id)
  File "/home/its_pt/Work/frappe_learn/frappe-bench/apps/frappe/frappe/utils/background_jobs.py", line 524, in is_job_enqueued
    return get_job_status(job_id) in (JobStatus.QUEUED, JobStatus.STARTED)
  File "/home/its_pt/Work/frappe_learn/frappe-bench/apps/frappe/frappe/utils/background_jobs.py", line 529, in get_job_status
    job = get_job(job_id)
  File "/home/its_pt/Work/frappe_learn/frappe-bench/apps/frappe/frappe/utils/background_jobs.py", line 536, in get_job
    return Job.fetch(create_job_id(job_id), connection=get_redis_conn())
  File "/home/its_pt/Work/frappe_learn/frappe-bench/env/lib/python3.10/site-packages/rq/job.py", line 591, in fetch
    job.refresh()
  File "/home/its_pt/Work/frappe_learn/frappe-bench/env/lib/python3.10/site-packages/rq/job.py", line 989, in refresh
    data = self.connection.hgetall(self.key)
  File "/home/its_pt/Work/frappe_learn/frappe-bench/env/lib/python3.10/site-packages/redis/commands/core.py", line 4954, in hgetall
    return self.execute_command("HGETALL", name)
  File "/home/its_pt/Work/frappe_learn/frappe-bench/env/lib/python3.10/site-packages/redis/client.py", line 533, in execute_command
    conn = self.connection or pool.get_connection(command_name, **options)
  File "/home/its_pt/Work/frappe_learn/frappe-bench/env/lib/python3.10/site-packages/redis/connection.py", line 1096, in get_connection
    connection.connect()
  File "/home/its_pt/Work/frappe_learn/frappe-bench/env/lib/python3.10/site-packages/redis/connection.py", line 270, in connect
    raise ConnectionError(self._error_message(e))
redis.exceptions.ConnectionError: Error 111 connecting to localhost:11000. Connection refused.
2023-12-05 16:04:11,836 ERROR scheduler Skipped queueing frappe.email.queue.flush because it was found in queue for library.test
2023-12-05 16:08:12,701 ERROR scheduler Skipped queueing frappe.email.queue.flush because it was found in queue for library.test
2023-12-05 16:12:13,679 ERROR scheduler Skipped queueing frappe.email.queue.flush because it was found in queue for library.test
2023-12-05 16:15:14,420 ERROR scheduler Skipped queueing frappe.twofactor.delete_all_barcodes_for_users because it was found in queue for library.test
2023-12-05 16:15:14,424 ERROR scheduler Skipped queueing frappe.website.doctype.web_page.web_page.check_publish_status because it was found in queue for library.test
2023-12-05 16:15:14,427 ERROR scheduler Skipped queueing frappe.oauth.delete_oauth2_data because it was found in queue for library.test
2023-12-05 16:16:14,750 ERROR scheduler Skipped queueing frappe.utils.global_search.sync_global_search because it was found in queue for library.test
2023-12-05 16:16:14,754 ERROR scheduler Skipped queueing frappe.email.doctype.email_account.email_account.notify_unreplied because it was found in queue for library.test
2023-12-05 16:16:14,765 ERROR scheduler Skipped queueing frappe.email.queue.flush because it was found in queue for library.test
2023-12-05 16:20:15,769 ERROR scheduler Skipped queueing frappe.email.doctype.email_account.email_account.notify_unreplied because it was found in queue for library.test
2023-12-05 16:20:15,790 ERROR scheduler Skipped queueing frappe.email.queue.flush because it was found in queue for library.test
2023-12-05 16:20:15,805 ERROR scheduler Skipped queueing frappe.email.doctype.email_account.email_account.pull because it was found in queue for library.test
2023-12-06 11:09:52,086 ERROR scheduler Exception in Enqueue Events for Site library.test
Traceback (most recent call last):
  File "/home/its_pt/Work/frappe_learn/frappe-bench/env/lib/python3.10/site-packages/pymysql/connections.py", line 644, in connect
    sock = socket.create_connection(
  File "/home/its_pt/.pyenv/versions/3.10.11/lib/python3.10/socket.py", line 845, in create_connection
    raise err
  File "/home/its_pt/.pyenv/versions/3.10.11/lib/python3.10/socket.py", line 833, in create_connection
    sock.connect(sa)
ConnectionRefusedError: [Errno 111] Connection refused

During handling of the above exception, another exception occurred:

Traceback (most recent call last):
  File "/home/its_pt/Work/frappe_learn/frappe-bench/apps/frappe/frappe/utils/scheduler.py", line 73, in enqueue_events_for_site
    if is_scheduler_inactive():
  File "/home/its_pt/Work/frappe_learn/frappe-bench/apps/frappe/frappe/utils/scheduler.py", line 110, in is_scheduler_inactive
    if is_scheduler_disabled(verbose=verbose):
  File "/home/its_pt/Work/frappe_learn/frappe-bench/apps/frappe/frappe/utils/scheduler.py", line 123, in is_scheduler_disabled
    frappe.db.get_single_value("System Settings", "enable_scheduler")
  File "/home/its_pt/Work/frappe_learn/frappe-bench/apps/frappe/frappe/database/database.py", line 776, in get_single_value
    ).run()
  File "/home/its_pt/Work/frappe_learn/frappe-bench/apps/frappe/frappe/query_builder/utils.py", line 87, in execute_query
    result = frappe.db.sql(query, params, *args, **kwargs)  # nosemgrep
  File "/home/its_pt/Work/frappe_learn/frappe-bench/apps/frappe/frappe/database/database.py", line 194, in sql
    self.connect()
  File "/home/its_pt/Work/frappe_learn/frappe-bench/apps/frappe/frappe/database/database.py", line 107, in connect
    self._conn = self.get_connection()
  File "/home/its_pt/Work/frappe_learn/frappe-bench/apps/frappe/frappe/database/mariadb/database.py", line 102, in get_connection
    conn = self._get_connection()
  File "/home/its_pt/Work/frappe_learn/frappe-bench/apps/frappe/frappe/database/mariadb/database.py", line 108, in _get_connection
    return self.create_connection()
  File "/home/its_pt/Work/frappe_learn/frappe-bench/apps/frappe/frappe/database/mariadb/database.py", line 111, in create_connection
    return pymysql.connect(**self.get_connection_settings())
  File "/home/its_pt/Work/frappe_learn/frappe-bench/env/lib/python3.10/site-packages/pymysql/connections.py", line 358, in __init__
    self.connect()
  File "/home/its_pt/Work/frappe_learn/frappe-bench/env/lib/python3.10/site-packages/pymysql/connections.py", line 711, in connect
    raise exc
pymysql.err.OperationalError: (2003, "Can't connect to MySQL server on '127.0.0.1' ([Errno 111] Connection refused)")
